BrunaGonzalez: dime cual es el error que me genera y como puedo solucionarlo:
(venv) C:\Users\Bruna González\global-exchange>python manage.py runserver
INFO 2025-09-23 22:03:51,930 autoreload 5516 14228 Watching for file changes with StatReloader
Performing system checks...

Exception in thread django-main-thread:
Traceback (most recent call last):
  File "C:\Program Files\Python313\Lib\threading.py", line 1043, in _bootstrap_inner
    self.run()
    ~~~~~~~~^^
  File "C:\Program Files\Python313\Lib\threading.py", line 994, in run
    self._target(*self._args, **self._kwargs)
    ~~~~~~~~~~~~^^^^^^^^^^^^^^^^^^^^^^^^^^^^^
  File "C:\Users\Bruna González\global-exchange\venv\Lib\site-packages\django\utils\autoreload.py", line 64, in wrapper
    fn(*args, **kwargs)
    ~~^^^^^^^^^^^^^^^^^
  File "C:\Users\Bruna González\global-exchange\venv\Lib\site-packages\django\core\management\commands\runserver.py", line 134, in inner_run
    self.check(**check_kwargs)
    ~~~~~~~~~~^^^^^^^^^^^^^^^^
  File "C:\Users\Bruna González\global-exchange\venv\Lib\site-packages\django\core\management\base.py", line 492, in check
    all_issues = checks.run_checks(
        app_configs=app_configs,
    ...<2 lines>...
        databases=databases,
    )
  File "C:\Users\Bruna González\global-exchange\venv\Lib\site-packages\django\core\checks\registry.py", line 89, in run_checks
    new_errors = check(app_configs=app_configs, databases=databases)
  File "C:\Users\Bruna González\global-exchange\venv\Lib\site-packages\django\core\checks\urls.py", line 136, in check_custom_error_handlers
    handler = resolver.resolve_error_handler(status_code)
  File "C:\Users\Bruna González\global-exchange\venv\Lib\site-packages\django\urls\resolvers.py", line 732, in resolve_error_handler
    callback = getattr(self.urlconf_module, "handler%s" % view_type, None)
                       ^^^^^^^^^^^^^^^^^^^
  File "C:\Users\Bruna González\global-exchange\venv\Lib\site-packages\django\utils\functional.py", line 47, in __get__
    res = instance.__dict__[self.name] = self.func(instance)
                                         ~~~~~~~~~^^^^^^^^^^
  File "C:\Users\Bruna González\global-exchange\venv\Lib\site-packages\django\urls\resolvers.py", line 711, in urlconf_module
    return import_module(self.urlconf_name)
  File "C:\Program Files\Python313\Lib\importlib\__init__.py", line 88, in import_module
    return _bootstrap._gcd_import(name[level:], package, level)
           ~~~~~~~~~~~~~~~~~~~~~~^^^^^^^^^^^^^^^^^^^^^^^^^^^^^^
  File "<frozen importlib._bootstrap>", line 1387, in _gcd_import
  File "<frozen importlib._bootstrap>", line 1360, in _find_and_load
  File "<frozen importlib._bootstrap>", line 1331, in _find_and_load_unlocked
  File "<frozen importlib._bootstrap>", line 935, in _load_unlocked
  File "<frozen importlib._bootstrap_external>", line 1026, in exec_module
  File "<frozen importlib._bootstrap>", line 488, in _call_with_frames_removed
  File "C:\Users\Bruna González\global-exchange\global_exchange\urls.py", line 18, in <module>
    path('transacciones/', include('transacciones.urls')),
                           ~~~~~~~^^^^^^^^^^^^^^^^^^^^^^
  File "C:\Users\Bruna González\global-exchange\venv\Lib\site-packages\django\urls\conf.py", line 39, in include
    urlconf_module = import_module(urlconf_module)
  File "C:\Program Files\Python313\Lib\importlib\__init__.py", line 88, in import_module
    return _bootstrap._gcd_import(name[level:], package, level)
           ~~~~~~~~~~~~~~~~~~~~~~^^^^^^^^^^^^^^^^^^^^^^^^^^^^^^
  File "<frozen importlib._bootstrap>", line 1387, in _gcd_import
    return _bootstrap._gcd_import(name[level:], package, level)
           ~~~~~~~~~~~~~~~~~~~~~~^^^^^^^^^^^^^^^^^^^^^^^^^^^^^^
  File "<frozen importlib._bootstrap>", line 1387, in _gcd_import
  File "<frozen importlib._bootstrap>", line 1360, in _find_and_load
  File "<frozen importlib._bootstrap>", line 1331, in _find_and_load_unlocked
  File "<frozen importlib._bootstrap>", line 935, in _load_unlocked
  File "<frozen importlib._bootstrap_external>", line 1026, in exec_module
  File "<frozen importlib._bootstrap>", line 488, in _call_with_frames_removed
  File "C:\Users\Bruna González\global-exchange\transacciones\urls.py", line 21, in <module>       
    path('<uuid:id_transaccion>/confirmar-retiro-efectivo/', views.VistaConfirmarRetiroEfectivo.as_view(), name='confirmar_retiro_efectivo'),
                                                             ^^^^^^^^^^^^^^^^^^^^^^^^^^^^^^^^^^    
AttributeError: module 'transacciones.views' has no attribute 'VistaConfirmarRetiroEfectivo'       


GitHub Copilot: El error es:

```
AttributeError: module 'transacciones.views' has no attribute 'VistaConfirmarRetiroEfectivo'
```

**¿Qué significa?**  
En tu archivo urls.py tienes una línea como esta:
```python
path('<uuid:id_transaccion>/confirmar-retiro-efectivo/', views.VistaConfirmarRetiroEfectivo.as_view(), name='confirmar_retiro_efectivo'),
```
Pero en el archivo views.py **no existe** la clase `VistaConfirmarRetiroEfectivo`.

---

## ¿Cómo lo soluciono?

1. **Verifica el nombre:**  
   - Asegúrate de que la clase se llame exactamente `VistaConfirmarRetiroEfectivo` en `views.py`.
   - Si tiene otro nombre, corrige el import en `urls.py`.

2. **Si no existe la clase:**  
   - Debes crearla en views.py. Por ejemplo:
   ````python
   # filepath: transacciones/views.py
   from django.views import View
   from django.shortcuts import render

   class VistaConfirmarRetiroEfectivo(View):
       def get(self, request, id_transaccion):
           # Lógica para mostrar el formulario de confirmación
           return render(request, 'transacciones/confirmar_retiro_efectivo.html')
   ````

3. **Si la clase existe pero el nombre es diferente:**  
   - Cambia en `urls.py` el nombre por el correcto.

---

**Resumen:**  
El error es porque Django no encuentra la vista `VistaConfirmarRetiroEfectivo`. Debes crearla o corregir el nombre en el archivo de URLs.

BrunaGonzalez: una solucion podria ser eliminar mi base de datos y vovler a tener uno nuevo ?

GitHub Copilot: No, **el error que tienes no se soluciona eliminando la base de datos**.  
El problema es de código: Django no encuentra la clase `VistaConfirmarRetiroEfectivo` en tu archivo views.py.  
Esto no tiene relación con la base de datos, sino con la definición de tus vistas.

**Solución correcta:**  
- Crea la clase `VistaConfirmarRetiroEfectivo` en views.py o corrige el nombre en tu archivo de URLs.

**Eliminar la base de datos solo es útil si tienes problemas de migraciones o datos corruptos, pero no para errores de importación de vistas.**

BrunaGonzalez: solo quiero que diga historial de transacciones:
{% if es_administrador %}Panel Administrativo - {% endif %}Historial de Transacciones

GitHub Copilot: Para que **siempre diga solo "Historial de Transacciones"** (sin importar si es administrador o no), reemplaza esa línea por:

````django
Historial de Transacciones
````

Así, elimina la condición y el texto de "Panel Administrativo".

BrunaGonzalez: cambia el codigo ue ya te proporcione 

GitHub Copilot: ````django
<!-- filepath: c:\Users\Bruna González\global-exchange\plantillas\transacciones\lista_transacciones.html -->
...código existente...
<h2>
    <i class="fas fa-history me-2"></i>
    Historial de Transacciones
</h2>
...código existente...
````

Reemplaza toda la línea:
```django
{% if es_administrador %}Panel Administrativo - {% endif %}Historial de Transacciones
```
por:
```django
Historial de Transacciones
```

BrunaGonzalez: cuando intento arrancar el servidor me genera el siguiente problema:
INFO 2025-09-24 09:29:50,019 basehttp 18048 7728 "GET / HTTP/1.1" 302 0
ERROR 2025-09-24 09:29:50,214 log 18048 7728 Internal Server Error: /divisas/
Traceback (most recent call last):
  File "C:\Users\Bruna González\global-exchange\venv\Lib\site-packages\django\core\handlers\exception.py", line 55, in inner
    response = get_response(request)
  File "C:\Users\Bruna González\global-exchange\venv\Lib\site-packages\django\core\handlers\base.py", line 197, in _get_response
    response = wrapped_callback(request, *callback_args, **callback_kwargs)
  File "C:\Users\Bruna González\global-exchange\venv\Lib\site-packages\django\views\generic\base.py", line 105, in view
    return self.dispatch(request, *args, **kwargs)
           ~~~~~~~~~~~~~^^^^^^^^^^^^^^^^^^^^^^^^^^
  File "C:\Users\Bruna González\global-exchange\venv\Lib\site-packages\django\views\generic\base.py", line 144, in dispatch
    return handler(request, *args, **kwargs)
  File "C:\Users\Bruna González\global-exchange\venv\Lib\site-packages\django\views\generic\base.py", line 228, in get
    context = self.get_context_data(**kwargs)
  File "C:\Users\Bruna González\global-exchange\divisas\views.py", line 72, in get_context_data    
    categoria = CategoriaCliente.objects.get(nombre='Minorista')
  File "C:\Users\Bruna González\global-exchange\venv\Lib\site-packages\django\db\models\manager.py", line 87, in manager_method
    return getattr(self.get_queryset(), name)(*args, **kwargs)
           ~~~~~~~~~~~~~~~~~~~~~~~~~~~~~~~~~~^^^^^^^^^^^^^^^^^
  File "C:\Users\Bruna González\global-exchange\venv\Lib\site-packages\django\db\models\query.py", line 633, in get
    raise self.model.DoesNotExist(
        "%s matching query does not exist." % self.model._meta.object_name
    )
clientes.models.CategoriaCliente.DoesNotExist: CategoriaCliente matching query does not exist.     
ERROR 2025-09-24 09:29:50,221 basehttp 18048 7728 "GET /divisas/ HTTP/1.1" 500 96954
dame las posibles soluciones

GitHub Copilot: El error es:

```
clientes.models.CategoriaCliente.DoesNotExist: CategoriaCliente matching query does not exist.
```

Esto significa que en tu base de datos **no existe una categoría de cliente con el nombre 'Minorista'** y tu código intenta buscarla.

---

## Posibles soluciones

1. **Crear la categoría 'Minorista' manualmente desde el admin de Django:**
   - Entra a `/admin` con tu superusuario.
   - Ve a "Categorías de Cliente" y crea una con nombre `Minorista`.

2. **Crear la categoría desde el shell de Django:**
   Ejecuta en terminal:
   ```bash
   python manage.py shell
   ```
   Luego:
   ```python
   from clientes.models import CategoriaCliente
   CategoriaCliente.objects.create(nombre='Minorista')
   exit()
   ```

3. **Ejecutar el comando de inicialización si existe:**
   Si tienes un comando como `python manage.py init_system`, ejecútalo.  
   Este comando suele crear datos básicos como categorías, monedas, etc.

4. **Agregar manejo de error en tu vista:**
   Para evitar que el sistema se caiga si no existe la categoría, puedes usar:
   ````python
   # filepath: divisas/views.py
   from clientes.models import CategoriaCliente

   try:
       categoria = CategoriaCliente.objects.get(nombre='Minorista')
   except CategoriaCliente.DoesNotExist:
       categoria = None  # O crea una nueva, o maneja el error como prefieras
   ````

---

**Recomendación:**  
Primero crea la categoría 'Minorista' en la base de datos. Así tu sistema funcionará como esperas.

BrunaGonzalez: creo que debo de eliminar mi base de datos porque puede ser el problema

GitHub Copilot: Eliminar la base de datos **no es necesario** para este error y puede hacerte perder información importante.

El problema es simplemente que **falta el registro "Minorista" en la tabla `CategoriaCliente`**.  
Puedes solucionarlo agregando ese registro, como te indiqué antes, sin borrar la base de datos.

**Solo elimina la base de datos si:**
- Está corrupta o dañada.
- No te importa perder todos los datos y quieres empezar desde cero.

**Solución recomendada:**  
Agrega la categoría faltante usando el admin de Django, el shell, o el comando de inicialización.  
¡Así no pierdes nada y resuelves el error!

BrunaGonzalez: INFO 2025-09-24 09:49:34,597 basehttp 10720 1944 "GET / HTTP/1.1" 302 0
ERROR 2025-09-24 09:49:34,822 log 10720 1944 Internal Server Error: /divisas/
Traceback (most recent call last):
  File "C:\Users\Bruna González\global-exchange\venv\Lib\site-packages\django\core\handlers\exception.py", line 55, in inner
    response = get_response(request)
  File "C:\Users\Bruna González\global-exchange\venv\Lib\site-packages\django\core\handlers\base.py", line 197, in _get_response
    response = wrapped_callback(request, *callback_args, **callback_kwargs)
  File "C:\Users\Bruna González\global-exchange\venv\Lib\site-packages\django\views\generic\base.py", line 105, in view
    return self.dispatch(request, *args, **kwargs)
           ~~~~~~~~~~~~~^^^^^^^^^^^^^^^^^^^^^^^^^^
  File "C:\Users\Bruna González\global-exchange\venv\Lib\site-packages\django\views\generic\base.py", line 144, in dispatch
    return handler(request, *args, **kwargs)
  File "C:\Users\Bruna González\global-exchange\venv\Lib\site-packages\django\views\generic\base.py", line 228, in get
    context = self.get_context_data(**kwargs)
  File "C:\Users\Bruna González\global-exchange\divisas\views.py", line 72, in get_context_data    
    categoria = CategoriaCliente.objects.get(nombre='Minorista')
  File "C:\Users\Bruna González\global-exchange\venv\Lib\site-packages\django\db\models\manager.py", line 87, in manager_method
    return getattr(self.get_queryset(), name)(*args, **kwargs)
           ~~~~~~~~~~~~~~~~~~~~~~~~~~~~~~~~~~^^^^^^^^^^^^^^^^^
  File "C:\Users\Bruna González\global-exchange\venv\Lib\site-packages\django\db\models\query.py", line 633, in get
    raise self.model.DoesNotExist(
        "%s matching query does not exist." % self.model._meta.object_name
    )
clientes.models.CategoriaCliente.DoesNotExist: CategoriaCliente matching query does not exist.     
ERROR 2025-09-24 09:49:34,827 basehttp 10720 1944 "GET /divisas/ HTTP/1.1" 500 96954
 cual es el error

GitHub Copilot: El error es:

```
clientes.models.CategoriaCliente.DoesNotExist: CategoriaCliente matching query does not exist.
```

**¿Qué significa?**  
Tu código intenta buscar una categoría de cliente con el nombre `'Minorista'` en la base de datos, pero **no existe** ese registro.

**Solución:**  
Debes crear una categoría llamada `'Minorista'` en la tabla `CategoriaCliente`.  
Puedes hacerlo desde el panel de administración de Django, el shell, o ejecutando el comando de inicialización si tu proyecto lo tiene.

**No es necesario eliminar la base de datos.**

BrunaGonzalez: problema solucioando 

GitHub Copilot: ¡Perfecto! Me alegra saber que el problema fue solucionado. Si necesitas más ayuda, aquí estoy.

BrunaGonzalez: que me quiere decir el siguiente texto:
You have 44 unapplied migration(s). Your project may not work properly until you apply the migrations for app(s): admin, auth, clientes, contenttypes, cuentas, divisas, notificaciones, otp_static, otp_totp, pagos, reportes, sessions, transacciones.
Run 'python manage.py migrate' to apply them.

GitHub Copilot: Ese mensaje te indica que tienes **44 migraciones pendientes** en tu proyecto Django.  
Las migraciones son cambios en la estructura de la base de datos (como crear o modificar tablas) que aún **no se han aplicado**.

**¿Qué debes hacer?**  
Ejecuta en tu terminal:

```bash
python manage.py migrate
```

Esto aplicará todas las migraciones pendientes y tu proyecto funcionará correctamente.  
Hasta que no lo hagas, algunas partes del sistema pueden no funcionar bien.

BrunaGonzalez: me salio este error:
DoesNotExist at /divisas/
CategoriaCliente matching query does not exist.
Request Method:	GET
Request URL:	http://127.0.0.1:8000/divisas/
Django Version:	5.2.4
Exception Type:	DoesNotExist
Exception Value:	
CategoriaCliente matching query does not exist.
Exception Location:	C:\Users\Bruna González\global-exchange\venv\Lib\site-packages\django\db\models\query.py, line 633, in get
Raised during:	divisas.views.VistaPanelControl
Python Executable:	C:\Users\Bruna González\global-exchange\venv\Scripts\python.exe
Python Version:	3.13.5
Python Path:	
['C:\\Users\\Bruna González\\global-exchange',
 'C:\\Program Files\\Python313\\python313.zip',
 'C:\\Program Files\\Python313\\DLLs',
 'C:\\Program Files\\Python313\\Lib',
 'C:\\Program Files\\Python313',
 'C:\\Users\\Bruna González\\global-exchange\\venv',
 'C:\\Users\\Bruna González\\global-exchange\\venv\\Lib\\site-packages']

GitHub Copilot: El error:

```
DoesNotExist at /divisas/
CategoriaCliente matching query does not exist.
```

significa que tu código está intentando buscar una categoría de cliente llamada **'Minorista'** (u otro nombre) en la base de datos, pero **no existe ese registro**.

---

## ¿Cómo lo soluciono?

Debes crear la categoría faltante en la base de datos.  
Como tu proyecto tiene un comando para inicializar datos básicos, solo ejecuta en la terminal:

```bash
python manage.py init_system
```

Este comando creará las categorías de clientes necesarias (incluyendo 'Minorista'), monedas, tasas, métodos de pago, etc.

---

**Resumen:**  
No es un error de código ni de instalación, solo falta un dato inicial en la base de datos.  
Corre el comando anterior y el error desaparecerá.

BrunaGonzalez: como lo hago ?

GitHub Copilot: Se ha buscado código base para obtener "como lo hago ?", 22 resultados

Para solucionar el error `CategoriaCliente matching query does not exist`, debes asegurarte de que la base de datos tenga las categorías de cliente necesarias (como "Minorista").  
Tu propio archivo README.md indica los pasos para inicializar los datos básicos del sistema.

**Sigue estos pasos en tu terminal:**

1. **Aplica las migraciones** (si no lo hiciste antes):
   ```bash
   python manage.py migrate
   ```

2. **Inicializa el sistema con datos básicos**:
   ```bash
   python manage.py init_system
   ```

Esto creará las categorías de cliente, monedas, tasas y otros datos necesarios para que tu sistema funcione correctamente.

Luego, puedes arrancar el servidor normalmente:
```bash
python manage.py runserver
```

**Resumen:**  
Solo ejecuta estos comandos en orden y el error desaparecerá.

BrunaGonzalez: eso hice recientemente y me genera error

GitHub Copilot: ¡Perfecto! Según tu archivo README.md, los pasos que seguiste son correctos:

1. Ejecutaste `python manage.py migrate`
2. Ejecutaste `python manage.py init_system`
3. Ejecutaste `python manage.py runserver`

**Sin embargo,** si después de esto sigues recibiendo el error:

```
CategoriaCliente matching query does not exist.
```

entonces **algo está fallando en la creación de la categoría 'Minorista'** durante el comando `init_system`.

---

## ¿Qué hacer ahora?

1. **Verifica si la categoría existe en la base de datos:**

   - Entra al admin de Django:  
     Ve a [http://127.0.0.1:8000/admin](http://127.0.0.1:8000/admin)
   - Busca la sección de **Categoría de Cliente** (`CategoriaCliente`).
   - Revisa si existe una categoría llamada **Minorista**.

2. **Si NO existe, créala manualmente:**

   - Haz clic en "Agregar categoría de cliente" y ponle el nombre `Minorista`.
   - Guarda.

3. **Si existe, revisa que el nombre esté exactamente igual** (sin espacios extras, mayúsculas, etc.).

---

## Alternativa: Crear la categoría desde el shell

Si no puedes acceder al admin, puedes crear la categoría desde el shell de Django:

```bash
python manage.py shell
```
Luego ejecuta:
```python
from clientes.models import CategoriaCliente
CategoriaCliente.objects.create(nombre='Minorista')
exit()
```

---

## Resumen

- El error es porque falta la categoría 'Minorista' en la base de datos.
- Si el comando `init_system` no la crea, agrégala manualmente desde el admin o el shell.
- No necesitas borrar la base de datos ni reinstalar nada.

¿Te gustaría que te ayude a revisar el código de `init_system` para ver por qué no crea la categoría?

BrunaGonzalez: ejecute lo que me dijiste y me genera error:
INFO 2025-09-24 12:22:27,999 basehttp 6152 14792 "GET / HTTP/1.1" 302 0
ERROR 2025-09-24 12:22:28,132 log 6152 14792 Internal Server Error: /divisas/
Traceback (most recent call last):
  File "C:\Users\Bruna González\global-exchange\venv\Lib\site-packages\django\core\handlers\exception.py", line 55, in inner
    response = get_response(request)
  File "C:\Users\Bruna González\global-exchange\venv\Lib\site-packages\django\core\handlers\base.py", line 197, in _get_response
    response = wrapped_callback(request, *callback_args, **callback_kwargs)
  File "C:\Users\Bruna González\global-exchange\venv\Lib\site-packages\django\views\generic\base.py", line 105, in view
    return self.dispatch(request, *args, **kwargs)
           ~~~~~~~~~~~~~^^^^^^^^^^^^^^^^^^^^^^^^^^
  File "C:\Users\Bruna González\global-exchange\venv\Lib\site-packages\django\views\generic\base.py", line 144, in dispatch
    return handler(request, *args, **kwargs)
  File "C:\Users\Bruna González\global-exchange\venv\Lib\site-packages\django\views\generic\base.py", line 228, in get
    context = self.get_context_data(**kwargs)
  File "C:\Users\Bruna González\global-exchange\divisas\views.py", line 72, in get_context_data
    categoria = CategoriaCliente.objects.get(nombre='RETAIL')
  File "C:\Users\Bruna González\global-exchange\venv\Lib\site-packages\django\db\models\manager.py", line 87, in manager_method
    return getattr(self.get_queryset(), name)(*args, **kwargs)
           ~~~~~~~~~~~~~~~~~~~~~~~~~~~~~~~~~~^^^^^^^^^^^^^^^^^
  File "C:\Users\Bruna González\global-exchange\venv\Lib\site-packages\django\db\models\query.py", line 633, in get 
    raise self.model.DoesNotExist(
        "%s matching query does not exist." % self.model._meta.object_name
    )
clientes.models.CategoriaCliente.DoesNotExist: CategoriaCliente matching query does not exist.
ERROR 2025-09-24 12:22:28,148 basehttp 6152 14792 "GET /divisas/ HTTP/1.1" 500 96964

(venv) C:\Users\Bruna González\global-exchange>python manage.py shell      
42 objects imported automatically (use -v 2 for details).

Ctrl click to launch VS Code Native REPL
Python 3.13.5 (tags/v3.13.5:6cb20a2, Jun 11 2025, 16:15:46) [MSC v.1943 64 bit (AMD64)] on win32
Type "help", "copyright", "credits" or "license" for more information.
(InteractiveConsole)
>>> from clientes.models import CategoriaCliente
>>> CategoriaCliente.objects.create(nombre='Minorista')
Traceback (most recent call last):
  File "C:\Users\Bruna González\global-exchange\venv\Lib\site-packages\django\db\backends\utils.py", line 105, in _execute
    return self.cursor.execute(sql, params)
           ~~~~~~~~~~~~~~~~~~~^^^^^^^^^^^^^
  File "C:\Users\Bruna González\global-exchange\venv\Lib\site-packages\django\db\backends\sqlite3\base.py", line 360, in execute
    return super().execute(query, params)
           ~~~~~~~~~~~~~~~^^^^^^^^^^^^^^^
sqlite3.IntegrityError: UNIQUE constraint failed: clientes_categoria.nombre

The above exception was the direct cause of the following exception:

Traceback (most recent call last):
  File "<console>", line 1, in <module>
  File "C:\Users\Bruna González\global-exchange\venv\Lib\site-packages\django\db\models\manager.py", line 87, in manager_method
    return getattr(self.get_queryset(), name)(*args, **kwargs)
           ~~~~~~~~~~~~~~~~~~~~~~~~~~~~~~~~~~^^^^^^^^^^^^^^^^^
  File "C:\Users\Bruna González\global-exchange\venv\Lib\site-packages\django\db\models\query.py", line 663, in create
    obj.save(force_insert=True, using=self.db)
    ~~~~~~~~^^^^^^^^^^^^^^^^^^^^^^^^^^^^^^^^^^
  File "C:\Users\Bruna González\global-exchange\venv\Lib\site-packages\django\db\models\base.py", line 902, in save 
    self.save_base(
    ~~~~~~~~~~~~~~^
        using=using,
        ^^^^^^^^^^^^
    ...<2 lines>...
        update_fields=update_fields,
        ^^^^^^^^^^^^^^^^^^^^^^^^^^^^
    )
    ^
  File "C:\Users\Bruna González\global-exchange\venv\Lib\site-packages\django\db\models\base.py", line 1008, in save_base
    updated = self._save_table(
        raw,
    ...<4 lines>...
        update_fields,
    )
  File "C:\Users\Bruna González\global-exchange\venv\Lib\site-packages\django\db\models\base.py", line 1169, in _save_table
    results = self._do_insert(
        cls._base_manager, using, fields, returning_fields, raw
    )
  File "C:\Users\Bruna González\global-exchange\venv\Lib\site-packages\django\db\models\base.py", line 1210, in _do_insert
    return manager._insert(
           ~~~~~~~~~~~~~~~^
        [self],
        ^^^^^^^
    ...<3 lines>...
        raw=raw,
        ^^^^^^^^
    )
    ^
  File "C:\Users\Bruna González\global-exchange\venv\Lib\site-packages\django\db\models\manager.py", line 87, in manager_method
    return getattr(self.get_queryset(), name)(*args, **kwargs)
           ~~~~~~~~~~~~~~~~~~~~~~~~~~~~~~~~~~^^^^^^^^^^^^^^^^^
  File "C:\Users\Bruna González\global-exchange\venv\Lib\site-packages\django\db\models\query.py", line 1868, in _insert
    return query.get_compiler(using=using).execute_sql(returning_fields)
           ~~~~~~~~~~~~~~~~~~~~~~~~~~~~~~~~~~~~~~~~~~~^^^^^^^^^^^^^^^^^^
  File "C:\Users\Bruna González\global-exchange\venv\Lib\site-packages\django\db\models\sql\compiler.py", line 1882, in execute_sql
    cursor.execute(sql, params)
    ~~~~~~~~~~~~~~^^^^^^^^^^^^^
  File "C:\Users\Bruna González\global-exchange\venv\Lib\site-packages\django\db\backends\utils.py", line 122, in execute
    return super().execute(sql, params)
           ~~~~~~~~~~~~~~~^^^^^^^^^^^^^
  File "C:\Users\Bruna González\global-exchange\venv\Lib\site-packages\django\db\backends\utils.py", line 79, in execute
    return self._execute_with_wrappers(
           ~~~~~~~~~~~~~~~~~~~~~~~~~~~^
        sql, params, many=False, executor=self._execute
        ^^^^^^^^^^^^^^^^^^^^^^^^^^^^^^^^^^^^^^^^^^^^^^^
    )
    ^
  File "C:\Users\Bruna González\global-exchange\venv\Lib\site-packages\django\db\backends\utils.py", line 92, in _execute_with_wrappers
    return executor(sql, params, many, context)
  File "C:\Users\Bruna González\global-exchange\venv\Lib\site-packages\django\db\backends\utils.py", line 100, in _execute
    with self.db.wrap_database_errors:
         ^^^^^^^^^^^^^^^^^^^^^^^^^^^^
  File "C:\Users\Bruna González\global-exchange\venv\Lib\site-packages\django\db\utils.py", line 91, in __exit__    
    raise dj_exc_value.with_traceback(traceback) from exc_value
  File "C:\Users\Bruna González\global-exchange\venv\Lib\site-packages\django\db\backends\utils.py", line 105, in _execute
    return self.cursor.execute(sql, params)
           ~~~~~~~~~~~~~~~~~~~^^^^^^^^^^^^^
  File "C:\Users\Bruna González\global-exchange\venv\Lib\site-packages\django\db\backends\sqlite3\base.py", line 360, in execute
    return super().execute(query, params)
           ~~~~~~~~~~~~~~~^^^^^^^^^^^^^^^
django.db.utils.IntegrityError: UNIQUE constraint failed: clientes_categoria.nombre
>>> exit()
yo copie las 3 lineas de codigo y pegue y ejecute juntass

GitHub Copilot: ¡Gracias por el detalle!  
El error que ves:

```
django.db.utils.IntegrityError: UNIQUE constraint failed: clientes_categoria.nombre
```

significa que **ya existe una categoría con el nombre 'Minorista'** en tu base de datos, por eso no te deja crear otra igual.

Sin embargo, tu error original es porque tu código busca una categoría llamada `'RETAIL'`:

```
categoria = CategoriaCliente.objects.get(nombre='RETAIL')
```

pero en la base de datos tienes `'Minorista'`.

---

## ¿Cómo lo soluciono?

Debes asegurarte de que el nombre que buscas en el código **coincida exactamente** con el que tienes en la base de datos.

### Opción 1: Cambia el nombre en la base de datos

Desde el shell de Django, cambia el nombre de la categoría existente:

```python
from clientes.models import CategoriaCliente
cat = CategoriaCliente.objects.get(nombre='Minorista')
cat.nombre = 'RETAIL'
cat.save()
```

### Opción 2: Cambia el nombre en tu código

Si prefieres usar `'Minorista'`, cambia en tu vista:

````python
# ...existing code...
categoria = CategoriaCliente.objects.get(nombre='Minorista')
# ...existing code...
````

---

**Resumen:**  
El nombre debe ser exactamente igual en el código y en la base de datos.  
Corrige uno de los dos y el error desaparecerá.

BrunaGonzalez: prefiero quedarme con retail

GitHub Copilot: Perfecto, si prefieres quedarte con `'RETAIL'`, solo necesitas asegurarte de que **exista una categoría con ese nombre exacto** en tu base de datos.

Hazlo así desde el shell de Django:

```python
from clientes.models import CategoriaCliente
CategoriaCliente.objects.get_or_create(nombre='RETAIL')
```

Esto creará la categoría `'RETAIL'` si no existe, o usará la existente si ya está.

Luego, tu código funcionará correctamente buscando `'RETAIL'` y no tendrás más ese error.  
No necesitas borrar ni modificar nada más.

BrunaGonzalez: como lo hago exactamente ?
dame los pasos detallados

GitHub Copilot: Claro, aquí tienes los **pasos detallados** para solucionar el error de la categoría `'RETAIL'` en tu proyecto Django, asegurando que todo funcione correctamente:

---

### 1. Activa tu entorno virtual

Si no lo tienes activo, ejecuta en tu terminal:

```bash
venv\Scripts\activate
```

---

### 2. Aplica las migraciones

Esto asegura que la base de datos tenga la estructura correcta:

```bash
python manage.py migrate
```

---

### 3. Crea la categoría `'RETAIL'` en la base de datos

Abre el shell de Django:

```bash
python manage.py shell
```

Dentro del shell, ejecuta:

```python
from clientes.models import CategoriaCliente
CategoriaCliente.objects.get_or_create(nombre='RETAIL')
exit()
```

Esto creará la categoría `'RETAIL'` si no existe, o usará la existente si ya está.

---

### 4. Arranca el servidor

Ahora puedes iniciar el servidor normalmente:

```bash
python manage.py runserver
```

---

### 5. Verifica en el navegador

Abre [http://127.0.0.1:8000/divisas/](http://127.0.0.1:8000/divisas/) y comprueba que ya no aparece el error.

---

**¡Listo!**  
Con estos pasos, tu sistema debería funcionar correctamente y no volverás a ver el error de la categoría `'RETAIL'`. Si tienes otro problema, dime el mensaje exacto y te ayudo.

BrunaGonzalez: me sale este aviso en la imagen pegada 

GitHub Copilot: El aviso que ves en la imagen es **normal** en Visual Studio Code cuando intentas pegar varias líneas de código en el terminal o en el shell interactivo de Python.

### ¿Qué significa?
Te pregunta si realmente quieres pegar varias líneas a la vez, para evitar errores accidentales.

### ¿Qué debes hacer?
Haz clic en **"Pegar"** para que se peguen las 3 líneas de código en el shell de Django.  
Luego presiona **Enter** si es necesario para ejecutar el código.

---

**Resumen:**  
Este mensaje es solo una advertencia de seguridad.  
Puedes continuar y pegar el código sin problema.

BrunaGonzalez: como aranco servidor si se encuentra asi: Ctrl click to launch VS Code Native REPL
Python 3.13.5 (tags/v3.13.5:6cb20a2, Jun 11 2025, 16:15:46) [MSC v.1943 64 bit (AMD64)] on win32
Type "help", "copyright", "credits" or "license" for more information.
(InteractiveConsole)
>>> from clientes.models import CategoriaCliente
>>> CategoriaCliente.objects.get_or_create(nombre='RETAIL')
(<CategoriaCliente: Minorista>, True)
>>> CategoriaCliente.objects.get_or_create(nombre='RETAIL')

GitHub Copilot: ¡Perfecto! Ya ejecutaste correctamente el código en el shell interactivo de Django y creaste la categoría `'RETAIL'`.

Ahora, **para arrancar el servidor**, primero debes **salir del shell interactivo**. Hazlo así:

1. Escribe:
   ```python
   exit()
   ```
   y presiona **Enter**.

2. Ahora estarás de nuevo en la terminal normal (donde ves el prompt como `(venv) C:\Users\Bruna González\global-exchange>`).

3. Ejecuta el comando para arrancar el servidor:
   ```bash
   python manage.py runserver
   ```

¡Listo!  
Abre tu navegador en [http://127.0.0.1:8000/](http://127.0.0.1:8000/) y tu proyecto debería funcionar correctamente.

BrunaGonzalez: en el perfil de usuario desaparecio transacciones, algo anda mal 

GitHub Copilot: Se ha buscado código base para obtener "en el perfil de usuario desaparecio transacciones, algo anda mal ", 20 resultados

Si en el perfil de usuario **desapareció la sección de transacciones**, puede deberse a uno de estos motivos principales:

---

### 1. El contexto no incluye transacciones

En tu vista de perfil (views.py), la clave es que el contexto debe tener la variable `mis_transacciones`:

```python
class VistaPerfil(LoginRequiredMixin, TemplateView):
    #...
    def get_context_data(self, **kwargs):
        contexto = super().get_context_data(**kwargs)
        contexto['usuario'] = self.request.user
        contexto['clientes'] = self.request.user.clientes.all()
        from transacciones.models import Transaccion
        try:
            contexto['mis_transacciones'] = Transaccion.objects.filter(
                usuario=self.request.user
            ).select_related('moneda_origen', 'moneda_destino').order_by('-fecha_creacion')[:5]
        except Exception:
            contexto['mis_transacciones'] = []
        return contexto
```

**Verifica que no haya errores en esta parte.**

---

### 2. El usuario no tiene transacciones

Si el usuario nunca ha hecho una transacción, la sección puede mostrar un mensaje como "Aún no has realizado ninguna transacción."  
Pero **la sección debería aparecer igual** (aunque vacía).

---

### 3. Error en la plantilla

En tu plantilla perfil.html, la sección de transacciones depende de la variable `mis_transacciones`:

```html
{% if mis_transacciones %}
    <!-- Tabla de transacciones -->
{% else %}
    <!-- Mensaje de que no hay transacciones -->
{% endif %}
```

**Si `mis_transacciones` no existe o hay un error en la vista, la sección puede no mostrarse.**

---

### 4. Error en el modelo o migraciones

Si hubo un error en las migraciones o el modelo `Transaccion` no está bien, la consulta puede fallar y la sección no se muestra.

---

## ¿Qué hacer?

1. **Revisa la consola del servidor**:  
   Si hay errores al cargar la vista de perfil, aparecerán ahí.

2. **Verifica que tienes transacciones en la base de datos** para ese usuario.

3. **Asegúrate de que la vista de perfil esté agregando `mis_transacciones` al contexto** (como en el ejemplo de arriba).

4. **Haz una prueba**:  
   En el shell de Django, ejecuta:
   ```python
   from transacciones.models import Transaccion
   from cuentas.models import Usuario
   usuario = Usuario.objects.get(email='TU_EMAIL')
   print(Transaccion.objects.filter(usuario=usuario))
   ```
   Si la lista está vacía, el usuario no tiene transacciones.

---

¿Quieres que revise el código de la vista o la plantilla para darte una solución más específica? Si tienes un error en consola, pégalo aquí.

BrunaGonzalez: creo que el problema radica desde que cambie minorista por retail

GitHub Copilot: Es muy probable. Si cambiaste `'Minorista'` por `'RETAIL'` en la base de datos, pero en otras partes del código o plantillas aún se usa `'Minorista'`, entonces esas funciones o vistas **no encontrarán la categoría** y pueden dejar de mostrar información relacionada (como las transacciones).

---

## ¿Qué debes hacer?

1. **Busca en tu código todas las referencias a `'Minorista'`**  
   Asegúrate de que **todas** estén cambiadas por `'RETAIL'`.

   Puedes buscar en VS Code usando `Ctrl + Shift + F` y escribiendo `Minorista`.

2. **Revisa tus vistas y plantillas**  
   Especialmente en las vistas que filtran o muestran transacciones según la categoría del usuario.

3. **Verifica la lógica de permisos o filtros**  
   Si alguna función depende de que el usuario sea de la categoría `'Minorista'`, ahora debe buscar `'RETAIL'`.

---

**Resumen:**  
El cambio de nombre debe ser consistente en **toda la aplicación**.  
Si dejas referencias a `'Minorista'`, esas partes no funcionarán correctamente.

¿Quieres que te ayude a buscar y cambiar todas las referencias en tu código?

BrunaGonzalez: Traceback (most recent call last):
  File "C:\Users\Bruna González\global-exchange\manage.py", line 22, in <module>
    main()
    ~~~~^^
  File "C:\Users\Bruna González\global-exchange\manage.py", line 18, in main
    execute_from_command_line(sys.argv)
    ~~~~~~~~~~~~~~~~~~~~~~~~~^^^^^^^^^^
  File "C:\Users\Bruna González\global-exchange\venv\Lib\site-packages\django\core\management\__init__.py", line 442, in execute_from_command_line
    utility.execute()
    ~~~~~~~~~~~~~~~^^
  File "C:\Users\Bruna González\global-exchange\venv\Lib\site-packages\django\core\management\__init__.py", line 416, in execute
    django.setup()
    ~~~~~~~~~~~~^^
  File "C:\Users\Bruna González\global-exchange\venv\Lib\site-packages\django\__init__.py", line 24, in setup       
    apps.populate(settings.INSTALLED_APPS)
    ~~~~~~~~~~~~~^^^^^^^^^^^^^^^^^^^^^^^^^
  File "C:\Users\Bruna González\global-exchange\venv\Lib\site-packages\django\apps\registry.py", line 116, in populate
    app_config.import_models()
    ~~~~~~~~~~~~~~~~~~~~~~~~^^
  File "C:\Users\Bruna González\global-exchange\venv\Lib\site-packages\django\apps\config.py", line 269, in import_models
    self.models_module = import_module(models_module_name)
                         ~~~~~~~~~~~~~^^^^^^^^^^^^^^^^^^^^
  File "C:\Program Files\Python313\Lib\importlib\__init__.py", line 88, in import_module
    return _bootstrap._gcd_import(name[level:], package, level)
           ~~~~~~~~~~~~~~~~~~~~~~^^^^^^^^^^^^^^^^^^^^^^^^^^^^^^
  File "<frozen importlib._bootstrap>", line 1387, in _gcd_import
  File "<frozen importlib._bootstrap>", line 1360, in _find_and_load
  File "<frozen importlib._bootstrap>", line 1331, in _find_and_load_unlocked
  File "<frozen importlib._bootstrap>", line 935, in _load_unlocked
  File "<frozen importlib._bootstrap_external>", line 1026, in exec_module
  File "<frozen importlib._bootstrap>", line 488, in _call_with_frames_removed
  File "C:\Users\Bruna González\global-exchange\tauser\models.py", line 5, in <module>
    from rest_framework import serializers
ModuleNotFoundError: No module named 'rest_framework'


GitHub Copilot: El error que tienes es:

```
ModuleNotFoundError: No module named 'rest_framework'
```

Esto significa que **no tienes instalado Django REST Framework**, pero tu proyecto lo necesita (lo importa en models.py).

---

## ¿Cómo lo soluciono?

Debes instalar el paquete `djangorestframework` en tu entorno virtual. Hazlo así:

1. Asegúrate de tener activado tu entorno virtual:
   ```bash
   venv\Scripts\activate
   ```

2. Instala Django REST Framework:
   ```bash
   pip install djangorestframework
   ```

3. (Opcional) Si tienes un archivo requirements.txt, agrega la línea:
   ```
   djangorestframework
   ```
   y luego ejecuta:
   ```bash
   pip install -r requirements.txt
   ```

4. Vuelve a intentar arrancar el servidor:
   ```bash
   python manage.py runserver
   ```

---

**Resumen:**  
El error es porque falta el paquete `djangorestframework`. Instálalo y tu proyecto debería funcionar.

BrunaGonzalez: que significa el none en la imagen pegada ?

GitHub Copilot: Se ha buscado código base para obtener "que significa el none en la imagen pegada ?", 29 resultados

El **"None"** que aparece en el campo "Usuario" de tu imagen significa que la variable o el valor que debería mostrarse ahí **no está definido** o **es nulo** en Python (es decir, su valor es `None`).

Esto suele ocurrir cuando:

- El objeto usuario no está siendo pasado correctamente al contexto de la plantilla.
- El filtro o búsqueda no encontró ningún usuario asociado.
- El campo que intentas mostrar está vacío o no asignado.

**¿Cómo solucionarlo?**
1. Verifica en la vista que estés pasando correctamente el usuario al contexto.
2. Asegúrate de que el usuario esté autenticado o seleccionado.
3. Si usas algo como `{{ usuario }}` en la plantilla, revisa que esa variable no sea `None`.

Si necesitas ayuda para rastrear el origen, dime en qué plantilla aparece y te ayudo a revisar el código.

BrunaGonzalez: que siginifica la Mcon flecha que apunta pra abajo ?

GitHub Copilot: En Visual Studio Code, la **"M"** junto a un archivo significa que ese archivo está **modificado** respecto a la última versión confirmada en tu sistema de control de versiones (por ejemplo, Git).

La **flecha que apunta hacia abajo** indica que hay **cambios pendientes de ser descargados (pull)** desde el repositorio remoto, o que hay cambios en el repositorio remoto que aún no tienes localmente.

**Resumen:**  
- **M:** Archivo modificado localmente.
- **Flecha hacia abajo:** Hay cambios remotos pendientes de descargar.

Esto te ayuda a saber qué archivos cambiaste y si tu repositorio local está desactualizado respecto al remoto.

BrunaGonzalez: solucionado

GitHub Copilot: ¡Perfecto! Si necesitas más ayuda, aquí estoy.